[2025-10-02 03:09:50] INFO root: init_logging: logfile=logs\log_20251002_010950.txt
[2025-10-02 03:09:50] INFO __main__: Logging initialized
[2025-10-02 03:09:53] INFO root: Config loaded from config\gui_config.json
[2025-10-02 03:11:40] CRITICAL root: Uncaught exception
Traceback (most recent call last):
  File "C:\Users\soyko\Documents\git2\Market\project assistant\env.model_0.9\0.9f\fibopkg5\trading_gui_extended.py", line 3044, in <module>
    except Exception as e:
  File "C:\Users\soyko\Documents\git2\Market\project assistant\env.model_0.9\0.9f\fibopkg5\trading_gui_extended.py", line 3040, in main
    if self.daemon.model is not None:
  File "C:\Users\soyko\AppData\Local\Programs\Python\Python310\lib\tkinter\__init__.py", line 1458, in mainloop
    self.tk.mainloop(n)
KeyboardInterrupt
